Workbook

Sheet Dashboard
A1: LIBRAPAY — Financial Model Dashboard
A2: Summary view — all figures pull automatically from P&L, Cash Flow, and Assumptions sheets.
A3: Metric | B3: Year 1 | C3: Year 2 | D3: Year 3
A4: REVENUE
A5: Total Revenue | B5: ='P&L'!B22 -> 130593 | C5: ='P&L'!C22 -> 777945 | D5: ='P&L'!D22 -> 2446665
A6: Total Operating Costs | B6: ='P&L'!B34 -> 114400 | C6: ='P&L'!C34 -> 117700 | D6: ='P&L'!D34 -> 196900
A7: EBITDA | B7: ='P&L'!B35 -> 16193 | C7: ='P&L'!C35 -> 660245 | D7: ='P&L'!D35 -> 2249765
A8: EBITDA Margin | B8: ='P&L'!B36 -> 0.12399593 | C8: ='P&L'!C36 -> 0.84870396 | D8: ='P&L'!D36 -> 0.91952311
A9: Closing Cash Balance | B9: ='Cash Flow'!B19 -> 91193 | C9: ='Cash Flow'!C19 -> 676438 | D9: ='Cash Flow'!D19 -> 2926203
A10: VOLUME
A11: Monthly Remittance Transactions | B11: =Assumptions!B5 -> 600 | C11: =Assumptions!B6 -> 2400 | D11: =Assumptions!B7 -> 9000
A12: Active Cash Agents | B12: =Assumptions!B16 -> 15 | C12: =Assumptions!B17 -> 100 | D12: =Assumptions!B18 -> 300
A13: Monthly Merchant Transactions | B13: =Assumptions!B11 -> 200 | C13: =Assumptions!B12 -> 2000 | D13: =Assumptions!B13 -> 10000
A14: FUNDING
A15: Seed Funding Required | B15: ='Funding Request'!B33 -> 167860 | C15: — | D15: —
A16: Grant (MASSIF/ADFI) | B16: =Assumptions!$B$43 -> 75000 | C16: — | D16: —
A17: Equity / Convertible Note | B17: =Assumptions!$B$44 -> 50000 | C17: — | D17: —
A18: Funding Gap | B18: ='Funding Request'!B42 -> 42860 | C18: — | D18: —
A20: Update assumptions in the 'Assumptions' sheet — all figures here recalculate automatically.

Sheet Assumptions
A1: LIBRAPAY — Financial Model Assumptions
A2: All values in EUR unless stated. Blue = input (change freely). Yellow = key cell requiring your input.
A3: Assumption | B3: Value | C3: Unit | D3: Notes / Source
A4: VOLUME ASSUMPTIONS — REMITTANCE
A5: Monthly transactions — Year 1 | B5: 600 | C5: count | D5: Conservative: ~20/day. Diaspora NL launch.
A6: Monthly transactions — Year 2 | B6: 2400 | C6: count | D6: Expansion: NL + USA corridor, agent network growth.
A7: Monthly transactions — Year 3 | B7: 9000 | C7: count | D7: Scale: 300/day across full network.
A8: Average transaction value (EUR) | B8: 175 | C8: EUR | D8: Based on World Bank data: avg $200 corridor, converted at 1.10 EUR/USD
A9: EUR/USD exchange rate | B9: 1.1 | C9: rate | D9: Assumed flat. Update as needed.
A10: VOLUME ASSUMPTIONS — MERCHANT PAYMENTS
A11: Monthly merchant transactions Y1 | B11: 200 | C11: count | D11: Small: pilot 10-20 merchants in Monrovia
A12: Monthly merchant transactions Y2 | B12: 2000 | C12: count | D12: Growth: 100+ merchants
A13: Monthly merchant transactions Y3 | B13: 10000 | C13: count | D13: Scale: broad Monrovia adoption
A14: Avg merchant transaction value | B14: 40 | C14: EUR | D14: Small retail: food, goods, services
A15: VOLUME ASSUMPTIONS — CASH AGENT NETWORK
A16: Number of agents — Year 1 | B16: 15 | C16: agents | D16: Target 10-20 agents in Monrovia pilot
A17: Number of agents — Year 2 | B17: 100 | C17: agents | D17: City-wide Monrovia coverage
A18: Number of agents — Year 3 | B18: 300 | C18: agents | D18: National + Sierra Leone expansion
A19: Cash-out transactions per agent/day | B19: 8 | C19: txns | D19: Conservative; M-Pesa agents do 20-30/day
A20: Avg cash-out amount (EUR) | B20: 120 | C20: EUR | D20: Mix of small and large withdrawals
A21: FEE & REVENUE ASSUMPTIONS
A22: Remittance fee (sender) | B22: 0.02 | C22: rate | D22: 2.0% vs industry avg 5.36%. Source: World Bank RPW 2026
A23: EUR→USD exchange spread | B23: 0.008 | C23: rate | D23: 0.8% on fiat conversion
A24: Cash-out fee | B24: 0.01 | C24: rate | D24: 1.0% on physical USD withdrawal
A25: Merchant acceptance fee | B25: 0.005 | C25: rate | D25: 0.5% per QR payment transaction
A26: Float yield (APY on USDT float) | B26: 0.045 | C26: rate | D26: 4.5% APY via Aave/Compound. Source: DeFi Llama avg 2025-26
A27: Clean-notes premium (% of cashout) | B27: 0.008 | C27: rate | D27: 0.8% premium for new-issue USD notes
A28: COST ASSUMPTIONS
A29: Technology / hosting (monthly) | B29: 1500 | C29: EUR | D29: AWS/cloud, API costs (Fireblocks, KYC, USSD)
A30: Technology — Year 1 build cost | B30: 35000 | C30: EUR | D30: App dev, wallet integration, USSD. Update with dev quote.
A31: Legal & regulatory (Year 1) | B31: 15000 | C31: EUR | D31: Liberian counsel + DNB Netherlands MiCA registration
A32: Legal & regulatory (Year 2+) | B32: 5000 | C32: EUR/yr | D32: Ongoing compliance, VASP licence application
A33: Salaries — Year 1 (founder only) | B33: 24000 | C33: EUR | D33: Assumes founder draws modest salary. Adjust to reality.
A34: Salaries — Year 2 | B34: 72000 | C34: EUR | D34: Founder + ops manager Liberia + part-time compliance
A35: Salaries — Year 3 | B35: 144000 | C35: EUR | D35: Full team: 4-5 staff
A36: Agent float — initial capital | B36: 50000 | C36: EUR | D36: Working capital to supply agents with USD cash. KEY INPUT.
A37: Agent float — Year 2 addition | B37: 75000 | C37: EUR | D37: Expand float as agent network grows
A38: Marketing & diaspora acquisition | B38: 6000 | C38: EUR/yr | D38: Community events, social media, referral incentives Y1
A39: Office & operations | B39: 3600 | C39: EUR/yr | D39: Monrovia operations base, travel, comms
A40: Banking & payment infrastructure | B40: 2400 | C40: EUR/yr | D40: Correspondent bank fees, USD shipment insurance
...

Sheet P&L
A1: LIBRAPAY — Profit & Loss Statement (3-Year Projection)
A2: All amounts in EUR | Blue = inputs on Assumptions sheet | Green = cross-sheet link | Black = formula
A3: Line Item | B3: Year 1 (2027) | C3: Year 2 (2028) | D3: Year 3 (2029) | E3: Notes
A4: REVENUE
A5: 1. Remittance Fees
A6: Monthly transactions | B6: =Assumptions!B5 -> 600 | C6: =Assumptions!B6 -> 2400 | D6: =Assumptions!B7 -> 9000 | E6: Assumptions!B5:B7
A7: Average transaction value (EUR) | B7: =Assumptions!$B$8 -> 175 | C7: =Assumptions!$B$8 -> 175 | D7: =Assumptions!$B$8 -> 175 | E7: Assumptions!B8
A8: Remittance fee rate | B8: =Assumptions!$B$22 -> 0.02 | C8: =Assumptions!$B$22 -> 0.02 | D8: =Assumptions!$B$22 -> 0.02 | E8: Assumptions!B22
A9: Remittance fee revenue (annual) | B9: =B6*B7*B8*12 -> 25200 | C9: =C6*C7*C8*12 -> 100800 | D9: =D6*D7*D8*12 -> 378000 | E9: Monthly txns × avg value × fee × 12
A10: EUR→USD exchange spread revenue | B10: =B6*B7*12*Assumptions!$B$23 -> 10080 | C10: =C6*C7*12*Assumptions!$B$23 -> 40320 | D10: =D6*D7*12*Assumptions!$B$23 -> 151200 | E10: Spread on converted volume. Assumptions!B23
A11: 2. Cash Agent Network Fees
A12: Number of agents | B12: =Assumptions!B16 -> 15 | C12: =Assumptions!B17 -> 100 | D12: =Assumptions!B18 -> 300 | E12: Assumptions!B16:B18
A13: Agent cash-out transactions (annual) | B13: =B12*Assumptions!$B$19*365 -> 43800 | C13: =C12*Assumptions!$B$19*365 -> 292000 | D13: =D12*Assumptions!$B$19*365 -> 876000 | E13: Agents × txns/agent/day × 365
A14: Cash-out fee revenue | B14: =B13*Assumptions!$B$20*Assumptions!$B$24 -> 52560 | C14: =C13*Assumptions!$B$20*Assumptions!$B$24 -> 350400 | D14: =D13*Assumptions!$B$20*Assumptions!$B$24 -> 1051200 | E14: Txns × avg cashout value × cash-out fee
A15: Clean-notes premium revenue | B15: =B13*Assumptions!$B$20*Assumptions!$B$27 -> 42048 | C15: =C13*Assumptions!$B$20*Assumptions!$B$27 -> 280320 | D15: =D13*Assumptions!$B$20*Assumptions!$B$27 -> 840960 | E15: Clean-notes premium on cash-out volume
A16: 3. Merchant Payment Fees
A17: Monthly merchant transactions | B17: =Assumptions!B11 -> 200 | C17: =Assumptions!B12 -> 2000 | D17: =Assumptions!B13 -> 10000 | E17: Assumptions!B11:B13
A18: Merchant fee revenue (annual) | B18: =B17*Assumptions!$B$14*Assumptions!$B$25*12 -> 480 | C18: =C17*Assumptions!$B$14*Assumptions!$B$25*12 -> 4800 | D18: =D17*Assumptions!$B$14*Assumptions!$B$25*12 -> 24000 | E18: Txns × avg value × fee × 12
A19: 4. Float Yield (Passive)
A20: Estimated float held (EUR) | B20: 5000 | C20: 29000 | D20: 29000 | E20: Working capital float at agents. Estimate — update once real float schedule known.
A21: Float yield revenue | B21: =B20*Assumptions!$B$26 -> 225 | C21: =C20*Assumptions!$B$26 -> 1305 | D21: =D20*Assumptions!$B$26 -> 1305 | E21: Float × APY. Assumptions!B26
A22: TOTAL REVENUE | B22: =B9+B10+B14+B15+B18+B21 -> 130593 | C22: =C9+C10+C14+C15+C18+C21 -> 777945 | D22: =D9+D10+D14+D15+D18+D21 -> 2446665 | E22: Sum of all revenue lines
A24: OPERATING COSTS
A25: Technology — Initial Build | B25: =Assumptions!$B$30 -> 35000 | C25: 0 | D25: 0 | E25: One-time app+wallet+USSD build, Year 1 only. Assumptions!B30
A26: Technology — Hosting & APIs | B26: =Assumptions!$B$29*12 -> 18000 | C26: =Assumptions!$B$29*12 -> 18000 | D26: =Assumptions!$B$29*12 -> 18000 | E26: Monthly hosting × 12. Assumptions!B29
A27: Legal & Regulatory | B27: =Assumptions!$B$31 -> 15000 | C27: =Assumptions!$B$32 -> 5000 | D27: =Assumptions!$B$32 -> 5000 | E27: Y1: Assumptions!B31. Y2+: Assumptions!B32 (ongoing)
A28: Salaries & Contractor Costs | B28: =Assumptions!$B$33 -> 24000 | C28: =Assumptions!$B$34 -> 72000 | D28: =Assumptions!$B$35 -> 144000 | E28: Assumptions!B33:B35
A29: Marketing & Diaspora Acquisition | B29: =Assumptions!$B$38 -> 6000 | C29: =Assumptions!$B$38 -> 6000 | D29: =Assumptions!$B$38 -> 6000 | E29: Flat annual per Assumptions!B38 — update if a growth-with-scale figure is preferred
A30: Office & Operations (Monrovia) | B30: =Assumptions!$B$39 -> 3600 | C30: =Assumptions!$B$39 -> 3600 | D30: =Assumptions!$B$39 -> 3600 | E30: Flat annual per Assumptions!B39
A31: Banking, USD Shipment & Insurance | B31: =Assumptions!$B$40 -> 2400 | C31: =Assumptions!$B$40 -> 2400 | D31: =Assumptions!$B$40 -> 2400 | E31: Flat annual per Assumptions!B40
A32: Subtotal Operating Costs (before contingency) | B32: =SUM(B25:B31) -> 104000 | C32: =SUM(C25:C31) -> 107000 | D32: =SUM(D25:D31) -> 179000 | E32: Pre-contingency subtotal
A33: Contingency (10%) | B33: =B32*Assumptions!$B$41 -> 10400 | C33: =C32*Assumptions!$B$41 -> 10700 | D33: =D32*Assumptions!$B$41 -> 17900 | E33: 10% of operating costs. Assumptions!B41
A34: TOTAL OPERATING COSTS | B34: =B32+B33 -> 114400 | C34: =C32+C33 -> 117700 | D34: =D32+D33 -> 196900 | E34: Total costs including contingency
A35: EBITDA (Operating Profit / Loss) | B35: =B22-B34 -> 16193 | C35: =C22-C34 -> 660245 | D35: =D22-D34 -> 2249765 | E35: Revenue minus all operating costs
A36: EBITDA Margin | B36: =IFERROR(B35/B22,0) -> 0.12399593 | C36: =IFERROR(C35/C22,0) -> 0.84870396 | D36: =IFERROR(D35/D22,0) -> 0.91952311 | E36: EBITDA as % of revenue
A37: Cumulative Surplus / (Deficit) | B37: =B35 -> 16193 | C37: =B37+C35 -> 676438 | D37: =C37+D35 -> 2926203 | E37: Running total from Year 1
A39: NOTE: This model uses conservative volume assumptions. Update blue cells in Assumptions sheet to model different scenarios. Depreciation, tax, and interest not included at this stage — to be added with legal/accounting advisor input.

Sheet Cash Flow
A1: LIBRAPAY — Cash Flow Statement (3-Year Projection)
A2: Cash position includes funding inflows. Working capital float is treated as capital deployment, not operating cost.
A3: Line Item | B3: Year 1 (2027) | C3: Year 2 (2028) | D3: Year 3 (2029) | E3: Notes
A4: OPERATING CASH FLOWS
A5: Total Revenue (from P&L) | B5: ='P&L'!B22 -> 130593 | C5: ='P&L'!C22 -> 777945 | D5: ='P&L'!D22 -> 2446665 | E5: Links to P&L Total Revenue row
A6: Total Operating Costs (from P&L) | B6: =-'P&L'!B34 -> -114400 | C6: =-'P&L'!C34 -> -117700 | D6: =-'P&L'!D34 -> -196900 | E6: Links to P&L Total Costs (shown negative)
A7: NET OPERATING CASH FLOW | B7: =B5+B6 -> 16193 | C7: =C5+C6 -> 660245 | D7: =D5+D6 -> 2249765 | E7: Operating inflow minus outflow
A8: INVESTING / CAPITAL ACTIVITIES
A9: Agent float deployment (cash held at agents) | B9: =-Assumptions!$B$36 -> -50000 | C9: =-Assumptions!$B$37 -> -75000 | D9: 0 | E9: Capital deployed as working float — held as USD asset. Assumptions!B36 (Y1), B37 (Y2 addition)
A10: Technology build (one-time capex) | B10: 0 | C10: 0 | D10: 0 | E10: Already recognised in P&L 'Technology — Initial Build' (Year 1); shown here at €0 to avoid double-counting
A11: NET INVESTING CASH FLOW | B11: =B9+B10 -> -50000 | C11: =C9+C10 -> -75000 | D11: =D9+D10 -> 0 | E11: Capital deployed
A12: FINANCING ACTIVITIES (FUNDING INFLOWS)
A13: Grant received (MASSIF / ADFI) | B13: =Assumptions!$B$43 -> 75000 | C13: 0 | D13: 0 | E13: Equity-free grant, received Month 1 of Year 1. Assumptions!B43
A14: Equity / Convertible note | B14: =Assumptions!$B$44 -> 50000 | C14: 0 | D14: 0 | E14: Angel / FMO Ventures seed, disbursed Month 3 of Year 1. Assumptions!B44
A15: Series A (placeholder) | B15: 0 | C15: 0 | D15: 0 | E15: [TO BE CONFIRMED — placeholder for Year 2/3 raise if needed]
A16: NET FINANCING CASH FLOW | B16: =SUM(B13:B15) -> 125000 | C16: =SUM(C13:C15) -> 0 | D16: =SUM(D13:D15) -> 0 | E16: Total funding received
A17: NET CASH MOVEMENT (Year) | B17: =B7+B11+B16 -> 91193 | C17: =C7+C11+C16 -> 585245 | D17: =D7+D11+D16 -> 2249765 | E17: Total cash in minus total cash out for the year
A18: Opening cash balance | B18: 0 | C18: =B19 -> 91193 | D18: =C19 -> 676438 | E18: Opening = prior year closing
A19: CLOSING CASH BALANCE | B19: =B18+B17 -> 91193 | C19: =C18+C17 -> 676438 | D19: =D18+D17 -> 2926203 | E19: Cash position at year end
A21: IMPORTANT: A negative closing balance indicates a funding gap. If Year 1 shows negative, increase the grant/equity amount in the Assumptions sheet until the balance is positive. The agent float is a capital asset (held as USD), not a loss.

Sheet Funding Request
A1: LIBRAPAY — Itemised Funding Request
A2: Seed funding requirement for Year 1 launch. Yellow cells = require your confirmation. All amounts EUR.
A3: Cost Item | B3: Amount (EUR) | C3: Category | D3: Notes
A4: A. TECHNOLOGY & INFRASTRUCTURE
A5: Mobile app development (iOS + Android) | B5: 20000 | C5: Capex | D5: React Native. Get 3 developer quotes. [YELLOW = ESTIMATE]
A6: Wallet infrastructure (Fireblocks/BitGo API setup) | B6: 5000 | C6: Capex | D6: Institutional custody API integration
A7: USSD gateway integration (Africa's Talking) | B7: 3000 | C7: Capex | D7: Feature phone access for non-smartphone users
A8: KYC/AML system (Sumsub or Smile Identity) | B8: 4000 | C8: Capex | D8: Identity verification — mandatory for AML compliance
A9: Cloud hosting setup (AWS/Azure Year 1) | B9: 2000 | C9: Opex | D9: First year hosting, domain, security certificates
A10: B. LEGAL & REGULATORY
A11: Liberian legal advisor (CBL engagement + MSB licence) | B11: 8000 | C11: Opex | D11: LOCAL LIBERIAN COUNSEL — critical path item. [ESTIMATE]
A12: Netherlands DNB registration (MiCA CASP) | B12: 3000 | C12: Opex | D12: EU crypto service provider registration
A13: Company formation (Liberia + NL holding structure) | B13: 2500 | C13: Opex | D13: Corporate structure setup — confirm with tax advisor
A14: AML compliance programme documentation | B14: 1500 | C14: Opex | D14: Policies, procedures, transaction monitoring setup
A15: C. WORKING CAPITAL — AGENT FLOAT
A16: Initial USD cash float for agent network | B16: =Assumptions!$B$36 -> 50000 | C16: Working Capital | D16: Physical USD held at agents for cash-out. KEY ITEM. Assumptions!B36
A17: Float management buffer (10%) | B17: 5000 | C17: Working Capital | D17: Reserve for float shortfall at busy agents
A18: D. OPERATIONS & TEAM
A19: Founder salary (12 months) | B19: =Assumptions!$B$33 -> 24000 | C19: Opex | D19: Assumptions!B33. Adjust to your actual requirement.
A20: Liberia operations manager (6 months, part-time) | B20: 6000 | C20: Opex | D20: On-the-ground agent recruitment and management
A21: Travel (NL ↔ Monrovia, Year 1) | B21: 4000 | C21: Opex | D21: 2-3 trips for agent setup, CBL meetings, market validation
A22: Monrovia operations base (12 months) | B22: 3600 | C22: Opex | D22: Office/co-working space, communications
A23: E. MARKETING & COMMUNITY
A24: Diaspora community launch events (Netherlands) | B24: 2000 | C24: Opex | D24: Liberian community events in Amsterdam/Rotterdam/Den Haag
A25: Digital marketing (Facebook/WhatsApp diaspora targeting) | B25: 2000 | C25: Opex | D25: Paid social, WhatsApp community sponsorship
A26: Referral incentive programme | B26: 2000 | C26: Opex | D26: First 500 users get reduced fee — acquisition cost
A27: F. WHOLESALE BANKNOTE SUPPLY CHAIN
A28: Initial wholesale banknote distributor relationship setup | B28: 2000 | C28: Opex | D28: Travelex/Moneycorp account opening, compliance, first shipment fees
A29: First USD note shipment (insurance + armoured freight) | B29: 3000 | C29: Opex | D29: Brinks/Loomis West Africa delivery to Monrovia. [ESTIMATE]
A30: Subtotal (pre-contingency) | B30: =SUM(B5:B9)+SUM(B11:B14)+SUM(B16:B17)+SUM(B19:B22)+SUM(B24:B26)+SUM(B28:B29) -> 152600 | D30: Sum of sections A-F
A31: G. CONTINGENCY
A32: Contingency (10% of above) | B32: =B30*Assumptions!$B$41 -> 15260 | C32: Reserve | D32: 10% buffer on total pre-contingency costs. Assumptions!B41
A33: TOTAL SEED FUNDING REQUIRED | B33: =B30+B32 -> 167860
A35: PROPOSED FUNDING STRUCTURE
A36: Source | B36: Amount (EUR) | C36: Type | D36: Notes
A37: FMO MASSIF Fund / ADFI Grant | B37: =Assumptions!$B$43 -> 75000 | C37: Grant (equity-free) | D37: Primary target. fmo.nl MASSIF. Apply first. Assumptions!B43
A38: Angel / FMO Ventures convertible note | B38: =Assumptions!$B$44 -> 50000 | C38: Convertible note/equity | D38: Secondary. FMO Ventures Program Series A/B. Assumptions!B44
A39: RVO Netherlands Enterprise Agency | B39: 0 | C39: Grant | D39: rvo.nl Africa Ecosystem Catalysts Facility
A40: Founder contribution (if any) | B40: 0 | C40: Equity | D40: [Add any personal investment here]
A41: Total Funding Identified | B41: =SUM(B37:B40) -> 125000
...
